Workbook

Sheet RawData
A1: S.No | B1: Cohort | C1: Enrollment number | D1: Name of the Student | E1: Specialization | F1: MobileNo | G1: Mail IDs | H1: Gender | I1: Name According to Bank | J1: Parent Mobile NO | K1: DOB | L1: Age | M1: 1 | N1: 2 | O1: 3 | P1: 4 | Q1: 5 | R1: 8 | S1: 9 | T1: 10 | U1: 11 | V1: 12 | W1: 15 | X1: 16 | Y1: 17 | Z1: 18 | AA1: 19 | AB1: 22 | AC1: 23 | AD1: 24 | AE1: 25 | AF1: 26 | AG1: 29 | AH1: 30 | AI1: 31
A2: 1 | B2: 1 | C2: 0223CPIT001 | D2: NIKITHA ADULA | E2: ITES | F2: 6399221384 | G2: nikitha.itesites@gmail.com | H2: Female | I2: =D2 -> NIKITHA ADULA | J2: 2120339506 | K2: 01.01.2005 | L2: 18 | M2: P | N2: P | O2: A | P2: P | Q2: P | R2: P | S2: P | T2: P | U2: A | V2: P | W2: P | X2: A | Y2: P | Z2: P | AA2: P | AB2: P | AC2: P | AD2: P | AE2: P | AF2: P | AG2: L | AH2: P | AI2: P
A3: 2 | B3: 1 | C3: 0223CPIT002 | D3: ADULA LIKHITHA | E3: Full Stack | F3: 8732960724 | G3: adulalikitha.fullstack@gmail.com | H3: Female | I3: =D3 -> ADULA LIKHITHA | J3: 2573691990 | K3: 06.10.2002 | L3: 21 | M3: P | N3: =CHOOSE(RANDBETWEEN(1,3),"P","A","L") -> L | AE3: P | AF3: P | AG3: L | AH3: A | AI3: L
A4: 3 | B4: 3 | C4: 0223CPIT003 | D4: AKASH RAJPOOT | E4: Full Stack | F4: 3928683138 | G4: akashrajpoot.fullstack@gmail.com | H4: Male | I4: =D4 -> AKASH RAJPOOT | J4: 8436624675 | K4: 09.06.2004 | L4: 19 | M4: P
A5: 4 | B5: 3 | C5: 0223CPIT004 | D5: ALOK KUMAR | E5: Full Stack | F5: 6302977515 | G5: alokkumar.fullstack@gmail.com | H5: Male | I5: =D5 -> ALOK KUMAR | J5: 2124694089 | K5: 28.03.2004 | L5: 19 | M5: P
A6: 5 | B6: 1 | C6: 0223CPIT005 | D6: AYUSHMAN SINGH BAGHEL | E6: Full Stack | F6: 3285643454 | G6: ayushmansinghbaghel.fullstack@gmail.com | H6: Male | I6: =D6 -> AYUSHMAN SINGH BAGHEL | J6: 6858212965 | K6: 02.12.2005 | L6: 18 | M6: A
A7: 6 | B7: 3 | C7: 0223CPIT006 | D7: B SANDEEP ROY | E7: ITES | F7: 6204804746 | G7: bsandeeproy.itesites@gmail.com | H7: Male | I7: =D7 -> B SANDEEP ROY | J7: 1456755625 | K7: 10.07.1998 | L7: 25 | M7: P
A8: 7 | B8: 3 | C8: 0223CPIT007 | D8: B. SRINIVASULU | E8: Full Stack | F8: 8402592334 | G8: bsrinivasulu.fullstack@gmail.com | H8: Male | I8: =D8 -> B. SRINIVASULU | J8: 1716014472 | K8: 16.06.2005 | L8: 18 | M8: P
A9: 8 | B9: 1 | C9: 0223CPIT008 | D9: BAIRI PRATHYUSH | E9: Full Stack | F9: 1770577932 | G9: bairiprathyush.fullstack@gmail.com | H9: Male | I9: =D9 -> BAIRI PRATHYUSH | J9: 2915576343 | K9: 02.08.2002 | L9: 21 | M9: P
A10: 9 | B10: 1 | C10: 0223CPIT009 | D10: BANDAPALLI GANGABHAVANI | E10: ITES | F10: 1087593685 | G10: bandapalligangabhavani.itesites@gmail.com | H10: Female | I10: =D10 -> BANDAPALLI GANGABHAVANI | J10: 7625492200 | K10: 10.11.2001 | L10: 22 | M10: A
A11: 10 | B11: 2 | C11: 0223CPIT010 | D11: BURRI VINITHA | E11: Full Stack | F11: 1693682470 | G11: burrivinitha.fullstack@gmail.com | H11: Female | I11: =D11 -> BURRI VINITHA | J11: 5262777453 | K11: 12.09.2004 | L11: 19 | M11: P
A12: 11 | B12: 2 | C12: 0223CPIT011 | D12: CHANDRA SAMPATH KUMAR | E12: Full Stack | F12: 1821308586 | G12: chandrasampathkumar.fullstack@gmail.com | H12: Male | I12: =D12 -> CHANDRA SAMPATH KUMAR | J12: 3313353085 | K12: 09.12.2002 | L12: 21 | M12: P
A13: 12 | B13: 1 | C13: 0223CPIT012 | D13: CHINNAKOTLA SURYA TEJA | E13: Full Stack | F13: 1683546545 | G13: chinnakotlasuryateja.fullstack@gmail.com | H13: Male | I13: =D13 -> CHINNAKOTLA SURYA TEJA | J13: 6225939300 | K13: 23.03.2001 | L13: 22 | M13: P
A14: 13 | B14: 3 | C14: 0223CPIT013 | D14: DASARI VIMALA | E14: Full Stack | F14: 5506439807 | G14: dasarivimala.fullstack@gmail.com | H14: Female | I14: =D14 -> DASARI VIMALA | J14: 5760440421 | K14: 01.10.2003 | L14: 20 | M14: P
A15: 14 | B15: 1 | C15: 0223CPIT014 | D15: DEVALLA DEEPAK | E15: ITES | F15: 3565997600 | G15: devalladeepak.itesites@gmail.com | H15: Male | I15: =D15 -> DEVALLA DEEPAK | J15: 8490923938 | K15: 30.01.2006 | L15: 17 | M15: P
... A33: 32 | B33: 1 | C33: 0223CPIT032 | D33: M. BALAJI | E33: ITES | F33: 7375541777 | G33: mbalaji.itesites@gmail.com | H33: Male | I33: =D33 -> M. BALAJI | J33: 2479994830 | K33: 29.07.2004 | L33: 19 | M33: P
A34: 33 | B34: 3 | C34: 0223CPIT033 | D34: MADHI VAISHNAVI | E34: ITES | F34: 2307603936 | G34: madhivaishnavi.itesites@gmail.com | H34: Female | I34: =D34 -> MADHI VAISHNAVI | J34: 2464662826 | K34: 37853 | L34: 20 | M34: P
A35: 34 | B35: 2 | C35: 0223CPIT034 | D35: MANDALOJU NAGALAXMI | E35: Full Stack | F35: 7539961295 | G35: mandalojunagalaxmi.fullstack@gmail.com | H35: Female | I35: =D35 -> MANDALOJU NAGALAXMI | J35: 7329763453 | K35: 15.07.2005 | L35: 18 | M35: P
A36: 35 | B36: 1 | C36: 0223CPIT035 | D36: MANIKYALA RAMADEVI | E36: Full Stack | F36: 8714929594 | G36: manikyalaramadevi.fullstack@gmail.com | H36: Female | I36: =D36 -> MANIKYALA RAMADEVI | J36: 1027318203 | K36: 10.07.2005 | L36: 18 | M36: P
A37: 36 | B37: 3 | C37: 0223CPIT036 | D37: MASKA PAVANI | E37: ITES | F37: 6748495954 | G37: maskapavani.itesites@gmail.com | H37: Female | I37: =D37 -> MASKA PAVANI | J37: 4012125534 | K37: 04.04.2006 | L37: 17 | M37: P
A38: 37 | B38: 3 | C38: 0223CPIT037 | D38: MEGHAGNI MUKHERJEE | E38: Full Stack | F38: 5598318903 | G38: meghagnimukherjee.fullstack@gmail.com | H38: Female | I38: =D38 -> MEGHAGNI MUKHERJEE | J38: 8606299440 | K38: 14.09.2005 | L38: 18 | M38: P
A39: 38 | B39: 1 | C39: 0223CPIT038 | D39: N LAXMI NARASIMHA | E39: Full Stack | F39: 5366755536 | G39: nlaxminarasimha.fullstack@gmail.com | H39: Male | I39: =D39 -> N LAXMI NARASIMHA | J39: 4099577077 | K39: 10.06.2005 | L39: 18 | M39: P
A40: 39 | B40: 3 | C40: 0223CPIT039 | D40: NANAPURAJ LAHARIKA | E40: ITES | F40: 5685425899 | G40: nanapurajlaharika.itesites@gmail.com | H40: Female | I40: =D40 -> NANAPURAJ LAHARIKA | J40: 3700957702 | K40: 15.04.2003 | L40: 20 | M40: P
A41: 40 | B41: 3 | C41: 0223CPIT040 | D41: NARRA VENKATA SAI | E41: ITES | F41: 8546891943 | G41: narravenkatasai.itesites@gmail.com | H41: Male | I41: =D41 -> NARRA VENKATA SAI | J41: 1351607642 | K41: 02.10.2002 | L41: 21 | M41: P
A42: 41 | B42: 3 | C42: 0223CPIT041 | D42: NAVUDU TEJESH | E42: ITES | F42: 7905481507 | G42: navudutejesh.itesites@gmail.com | H42: Male | I42: =D42 -> NAVUDU TEJESH | J42: 4584578764 | K42: 30.11.2005 | L42: 18 | M42: P
A43: 42 | B43: 2 | C43: 0223CPIT042 | D43: PALLEY SHRAVANI | E43: ITES | F43: 5681445328 | G43: palleyshravani.itesites@gmail.com | H43: Female | I43: =D43 -> PALLEY SHRAVANI | J43: 7661428150 | K43: 38337 | L43: 19 | M43: P
A44: 43 | B44: 2 | C44: 0223CPIT043 | D44: PAPAKANTI RAJU | E44: Full Stack | F44: 1576469041 | G44: papakantiraju.fullstack@gmail.com | H44: Male | I44: =D44 -> PAPAKANTI RAJU | J44: 3324864700 | K44: 02.10.2001 | L44: 22 | M44: P
A45: 44 | B45: 2 | C45: 0223CPIT044 | D45: PRATAPAGIRI NEELAKANTA SASTRY | E45: Full Stack | F45: 7244391357 | G45: pratapagirineelakantasastry.fullstack@gmail.com | H45: Male | I45: =D45 -> PRATAPAGIRI NEELAKANTA SASTRY | J45: 1344765434 | K45: 26.06.1999 | L45: 24 | M45: P
A46: 45 | B46: 1 | C46: 0223CPIT045 | D46: PRAVEEN RAJPOOT | E46: Full Stack | F46: 5713887644 | G46: praveenrajpoot.fullstack@gmail.com | H46: Male | I46: =D46 -> PRAVEEN RAJPOOT | J46: 8922958342 | K46: 04.06.2004 | L46: 19 | M46: P
A47: 46 | B47: 2 | C47: 0223CPIT046 | D47: R. VIGNESH | E47: ITES | F47: 4360003876 | G47: rvignesh.itesites@gmail.com | H47: Male | I47: =D47 -> R. VIGNESH | J47: 6311928736 | K47: 13.10.2004 | L47: 19 | M47: P
A48: 47 | B48: 2 | C48: 0223CPIT047 | D48: RACHAMANDUGU AJAYKUMAR | E48: Full Stack | F48: 6232183694 | G48: rachamanduguajaykumar.fullstack@gmail.com | H48: Male | I48: =D48 -> RACHAMANDUGU AJAYKUMAR | J48: 1358146481 | K48: 09.09.2004 | L48: 19 | M48: P
A49: 48 | B49: 3 | C49: 0223CPIT048 | D49: REVALLI NAGESHWARI | E49: Full Stack | F49: 6682877186 | G49: revallinageshwari.fullstack@gmail.com | H49: Female | I49: =D49 -> REVALLI NAGESHWARI | J49: 7997007047 | K49: 10.04.2003 | L49: 20 | M49: A
A50: 49 | B50: 3 | C50: 0223CPIT049 | D50: ROHIT REDDY | E50: ITES | F50: 8911831176 | G50: rohitreddy.itesites@gmail.com | H50: Male | I50: =D50 -> ROHIT REDDY | J50: 6665134788 | K50: 25.12.2005 | L50: 18 | M50: P
A51: 50 | B51: 3 | C51: 0223CPIT050 | D51: RUCHI RANJAN | E51: Full Stack | F51: 5328455783 | G51: ruchiranjan.fullstack@gmail.com | H51: Female | I51: =D51 -> RUCHI RANJAN | J51: 1065242166 | K51: 02.02.2005 | L51: 18 | M51: A
A52: 51 | B52: 1 | C52: 0223CPIT051 | D52: SHAIK FAHAD | E52: ITES | F52: 4825148027 | G52: shaikfahad.itesites@gmail.com | H52: Male | I52: =D52 -> SHAIK FAHAD | J52: 1828010878 | K52: 13.09.2004 | L52: 19 | M52: P
A53: 52 | B53: 3 | C53: 0223CPIT052 | D53: SHAIK SAMEER AHMED | E53: Full Stack | F53: 3228331930 | G53: shaiksameerahmed.fullstack@gmail.com | H53: Male | I53: =D53 -> SHAIK SAMEER AHMED | J53: 6717092554 | K53: 26.12.2003 | L53: 20 | M53: A
A54: 53 | B54: 1 | C54: 0223CPIT053 | D54: SHEJUL BALAJI RAMESHWAR | E54: Full Stack | F54: 7158666834 | G54: shejulbalajirameshwar.fullstack@gmail.com | H54: Male | I54: =D54 -> SHEJUL BALAJI RAMESHWAR | J54: 7178012275 | K54: 23.09.2003 | L54: 20 | M54: P
A55: 54 | B55: 2 | C55: 0223CPIT054 | D55: SHOAIB AKHTAR | E55: Full Stack | F55: 7998839021 | G55: shoaibakhtar.fullstack@gmail.com | H55: Male | I55: =D55 -> SHOAIB AKHTAR | J55: 1247692282 | K55: 05.06.2004 | L55: 19 | M55: A
... A78: 77 | B78: 1 | C78: 0223CPIT077 | D78: YARRA NAVYA SAHITHI | E78: Full Stack | F78: 6927479136 | G78: yarranavyasahithi.fullstack@gmail.com | H78: Female | I78: =D78 -> YARRA NAVYA SAHITHI | J78: 7539369224 | K78: 10.10.2002 | L78: 21 | M78: P
A79: 78 | B79: 1 | C79: 0223CPIT078 | D79: M. Aravind | E79: Full Stack | F79: 8625176197 | G79: maravind.fullstack@gmail.com | H79: Male | I79: =D79 -> M. Aravind | J79: 5862892304 | K79: 37126 | L79: 22 | M79: P
...

Sheet Vlookup
D5: Enrollment number | E5: Name of the Student | F5: Specialization | G5: MobileNo | H5: Mail IDs | I5: Gender
D6: 0223CPIT046 | E6: =VLOOKUP($D$6,RawData!$C$2:$H$82,2,FALSE) -> R. VIGNESH | F6: =VLOOKUP($D$6,RawData!$C$2:$H$82,3,FALSE) -> ITES | G6: =VLOOKUP($D$6,RawData!$C$2:$H$82,4,FALSE) -> 4360003876 | H6: =VLOOKUP($D$6,RawData!$C$2:$H$82,5,FALSE) -> rvignesh.itesites@gmail.com | I6: =VLOOKUP($D$6,RawData!$C$2:$H$82,6,FALSE) -> Male

Sheet VData
A1: Student Code | B1: Student Name | C1: Marks
A2: AF05174237 | B2: Machapatri G Sai Chiru | C2: 83
A3: AF05199372 | B3: Shaikh Juned | C3: 94
A4: AF05202233 | B4: Chavva manikanta | C4: 66
A5: AF05202244 | B5: Nangunoori Tanmai | C5: 97
A6: AF05202247 | B6: T Srivatshav | C6: 70
A7: AF05202426 | B7: T Keerthan kumar | C7: 56
A8: AF05202427 | B8: Kuruva Poojitha | C8: 100
A9: AF05202436 | B9: Vemula Nehru Nithish | C9: 96
A10: AF05202478 | B10: Priyanka Badiger | C10: 61
A11: AF05202482 | B11: Bandi Niharika varma | C11: 60
A12: AF05202485 | B12: Gorpadi parimala | C12: 93
A13: AF05202513 | B13: Maroju Shiva kumar | C13: 86
... A26: AF05208247 | B26: Gangula Mallesh | C26: 74

Sheet VResult
E5: Student Code | F5: Student Name | G5: Marks
E6: AF05202522 | F6: =UPPER(VLOOKUP(E6,VData!$A$2:$C$26,2,FALSE)) -> KANCHARL A ASHWINI | G6: =VLOOKUP(E6,VData!$A$2:$C$26,3,FALSE) -> 56

Sheet VMatch

Sheet HData
B2: Enrollment number | C2: 0223CPIT001 | D2: 0223CPIT002 | E2: 0223CPIT003 | F2: 0223CPIT004 | G2: 0223CPIT005 | H2: 0223CPIT006 | I2: 0223CPIT007 | J2: 0223CPIT008 | K2: 0223CPIT009 | L2: 0223CPIT010 | M2: 0223CPIT011 | N2: 0223CPIT012 | O2: 0223CPIT013 | P2: 0223CPIT014 | Q2: 0223CPIT015 | R2: 0223CPIT016 | S2: 0223CPIT017 | T2: 0223CPIT018 | U2: 0223CPIT019 | V2: 0223CPIT020 | W2: 0223CPIT021 | X2: 0223CPIT022 | Y2: 0223CPIT023 | Z2: 0223CPIT024 | AA2: 0223CPIT025 | AB2: 0223CPIT026 | AC2: 0223CPIT027 | AD2: 0223CPIT028 | AE2: 0223CPIT029 | AF2: 0223CPIT030 | AG2: 0223CPIT031 | AH2: 0223CPIT032 | AI2: 0223CPIT033 | AJ2: 0223CPIT034 | AK2: 0223CPIT035 | AL2: 0223CPIT036 | AM2: 0223CPIT037 | AN2: 0223CPIT038 | AO2: 0223CPIT039 | AP2: 0223CPIT040 | AQ2: 0223CPIT041 | AR2: 0223CPIT042 | AS2: 0223CPIT043 | AT2: 0223CPIT044 | AU2: 0223CPIT045 | AV2: 0223CPIT046 | AW2: 0223CPIT047 | AX2: 0223CPIT048 | AY2: 0223CPIT049 | AZ2: 0223CPIT050 | BA2: 0223CPIT051 | BB2: 0223CPIT052 | BC2: 0223CPIT053 | BD2: 0223CPIT054 | BE2: 0223CPIT055 | BF2: 0223CPIT056 | BG2: 0223CPIT057 | BH2: 0223CPIT058 | BI2: 0223CPIT059 | BJ2: 0223CPIT060 | BK2: 0223CPIT061 | BL2: 0223CPIT062 | BM2: 0223CPIT063 | BN2: 0223CPIT064 | BO2: 0223CPIT065 | BP2: 0223CPIT066 | BQ2: 0223CPIT067 | BR2: 0223CPIT068 | BS2: 0223CPIT069 | BT2: 0223CPIT070 | BU2: 0223CPIT071 | BV2: 0223CPIT072 | BW2: 0223CPIT073 | BX2: 0223CPIT074 | BY2: 0223CPIT075 | BZ2: 0223CPIT076 | CA2: 0223CPIT077 | CB2: 0223CPIT078 | CC2: 0223CPIT079 | CD2: 0223CPIT080
B3: Name of the Student | C3: NIKITHA ADULA | D3: ADULA LIKHITHA | E3: AKASH RAJPOOT | F3: ALOK KUMAR | G3: AYUSHMAN SINGH BAGHEL | H3: B SANDEEP ROY | I3: B. SRINIVASULU | J3: BAIRI PRATHYUSH | K3: BANDAPALLI GANGABHAVANI | L3: BURRI VINITHA | M3: CHANDRA SAMPATH KUMAR | N3: CHINNAKOTLA SURYA TEJA | O3: DASARI VIMALA | P3: DEVALLA DEEPAK | Q3: DEVKATHE KOMAL | R3: EERAMMAGARI RAVITEJA | S3: ELLENDULA SUPRIYA | T3: GADIYARAM VARSHA | U3: GAIKWAD SRUSHTI | V3: GAJJELA GIRI | W3: GARAPATI GAYATHRI | X3: GOLI SAI LOKESH | Y3: GURRAM YAMINI | Z3: HARI OM RAI | AA3: JADHAV YOGESH DHARAMSIGH | AB3: K. SANTOSHI | AC3: KALIGOTA NIHARIKA | AD3: KALPANA KODARI | AE3: KANCHA AKASH | AF3: KASTURI SAI MAHESH | AG3: LOVE TIWARI | AH3: M. BALAJI | AI3: MADHI VAISHNAVI | AJ3: MANDALOJU NAGALAXMI | AK3: MANIKYALA RAMADEVI | AL3: MASKA PAVANI | AM3: MEGHAGNI MUKHERJEE | AN3: N LAXMI NARASIMHA | AO3: NANAPURAJ LAHARIKA | AP3: NARRA VENKATA SAI | AQ3: NAVUDU TEJESH | AR3: PALLEY SHRAVANI | AS3: PAPAKANTI RAJU | AT3: PRATAPAGIRI NEELAKANTA SASTRY | AU3: PRAVEEN RAJPOOT | AV3: R. VIGNESH | AW3: RACHAMANDUGU AJAYKUMAR | AX3: REVALLI NAGESHWARI | AY3: ROHIT REDDY | AZ3: RUCHI RANJAN | BA3: SHAIK FAHAD | BB3: SHAIK SAMEER AHMED | BC3: SHEJUL BALAJI RAMESHWAR | BD3: SHOAIB AKHTAR | BE3: SINGAM KRISHNA VENI | BF3: SINGUDASU PALLAVI | BG3: SUBHASHIS PAL | BH3: SUJEET KUMAR | BI3: SURUCHI RANJAN | BJ3: SUVENDU KHATUA | BK3: SYED ABDUL HAKEEM | BL3: SYED ABDUL HALEEM | BM3: SYED ADIL | BN3: VELUPULA SUNIL KUMAR | BO3: BALA CHARY | BP3: BANDARI SRUJANA | BQ3: DURGA PRASAD | BR3: K PAVANI | BS3: M KOMAL RAJ | BT3: MEDI SANGEETHA | BU3: N.PARAMESH | BV3: NAGA CHANDU V | BW3: S SAMEER | BX3: SALVADI VENKATESH | BY3: UPPUNUTHALA PURUSHOTHAM | BZ3: VINAY KUMAR | CA3: YARRA NAVYA SAHITHI | CB3: M. Aravind | CC3: Surya Kiran | CD3: B Aravind
B4: Specialization | C4: ITES | D4: Full Stack | E4: Full Stack | F4: Full Stack | G4: Full Stack | H4: ITES | I4: Full Stack | J4: Full Stack | K4: ITES | L4: Full Stack | M4: Full Stack | N4: Full Stack | O4: Full Stack | P4: ITES | Q4: Full Stack | R4: Full Stack | S4: ITES | T4: Full Stack | U4: Full Stack | V4: ITES | W4: ITES | X4: Full Stack | Y4: Full Stack | Z4: Full Stack | AA4: Full Stack | AB4: Full Stack | AC4: ITES | AD4: Full Stack | AE4: Full Stack | AF4: Full Stack | AG4: Full Stack | AH4: ITES | AI4: ITES | AJ4: Full Stack | AK4: Full Stack | AL4: ITES | AM4: Full Stack | AN4: Full Stack | AO4: ITES | AP4: ITES | AQ4: ITES | AR4: ITES | AS4: Full Stack | AT4: Full Stack | AU4: Full Stack | AV4: ITES | AW4: Full Stack | AX4: Full Stack | AY4: ITES | AZ4: Full Stack | BA4: ITES | BB4: Full Stack | BC4: Full Stack | BD4: Full Stack | BE4: Full Stack | BF4: Full Stack | BG4: ITES | BH4: Full Stack | BI4: Full Stack | BJ4: ITES | BK4: Full Stack | BL4: Full Stack | BM4: ITES | BN4: Full Stack | BO4: ITES | BP4: Full Stack | BQ4: Full Stack | BR4: Full Stack | BS4: ITES | BT4: Full Stack | BU4: Full Stack | BV4: ITES | BW4: Full Stack | BX4: ITES | BY4: ITES | BZ4: Full Stack | CA4: Full Stack | CB4: Full Stack | CC4: Full Stack | CD4: Full Stack
B5: MobileNo | C5: 6399221384 | D5: 8732960724 | E5: 3928683138 | F5: 6302977515 | G5: 3285643454 | H5: 6204804746 | I5: 8402592334 | J5: 1770577932 | K5: 1087593685 | L5: 1693682470 | M5: 1821308586 | N5: 1683546545 | O5: 5506439807 | P5: 3565997600 | Q5: 2685014153 | R5: 8144007188 | S5: 5451418853 | T5: 2352093828 | U5: 4851546652 | V5: 6604423032 | W5: 4267924443 | X5: 2776428499 | Y5: 2344591250 | Z5: 4564000793 | AA5: 7831800139 | AB5: 1359937879 | AC5: 8357059907 | AD5: 8195300576 | AE5: 3908490120 | AF5: 6654686097 | AG5: 3176554504 | AH5: 7375541777 | AI5: 2307603936 | AJ5: 7539961295 | AK5: 8714929594 | AL5: 6748495954 | AM5: 5598318903 | AN5: 5366755536 | AO5: 5685425899 | AP5: 8546891943 | AQ5: 7905481507 | AR5: 5681445328 | AS5: 1576469041 | AT5: 7244391357 | AU5: 5713887644 | AV5: 4360003876 | AW5: 6232183694 | AX5: 6682877186 | AY5: 8911831176 | AZ5: 5328455783 | BA5: 4825148027 | BB5: 3228331930 | BC5: 7158666834 | BD5: 7998839021 | BE5: 8550635195 | BF5: 8733465367 | BG5: 6153044829 | BH5: 4496254693 | BI5: 2881088394 | BJ5: 3401449282 | BK5: 4405995363 | BL5: 2219599156 | BM5: 3482112190 | BN5: 8411360361 | BO5: 2842414479 | BP5: 5876113945 | BQ5: 4273126076 | BR5: 8077085042 | BS5: 8112643867 | BT5: 3685782386 | BU5: 6205596324 | BV5: 6578497608 | BW5: 2602080020 | BX5: 8796416295 | BY5: 5978571640 | BZ5: 5716170881 | CA5: 6927479136 | CB5: 8625176197 | CC5: 3221738150 | CD5: 2217423855
B6: Mail IDs | C6: nikitha.itesites@gmail.com | D6: adulalikitha.fullstack@gmail.com | E6: akashrajpoot.fullstack@gmail.com | F6: alokkumar.fullstack@gmail.com | G6: ayushmansinghbaghel.fullstack@gmail.com | H6: bsandeeproy.itesites@gmail.com | I6: bsrinivasulu.fullstack@gmail.com | J6: bairiprathyush.fullstack@gmail.com | K6: bandapalligangabhavani.itesites@gmail.com | L6: burrivinitha.fullstack@gmail.com | M6: chandrasampathkumar.fullstack@gmail.com | N6: chinnakotlasuryateja.fullstack@gmail.com | O6: dasarivimala.fullstack@gmail.com | P6: devalladeepak.itesites@gmail.com | Q6: devkathekomal.fullstack@gmail.com | R6: eerammagariraviteja.fullstack@gmail.com | S6: ellendulasupriya.itesites@gmail.com | T6: gadiyaramvarsha.fullstack@gmail.com | U6: gaikwadsrushti.fullstack@gmail.com | V6: gajjelagiri.itesites@gmail.com | W6: garapatigayathri.itesites@gmail.com | X6: golisailokesh.fullstack@gmail.com | Y6: gurramyamini.fullstack@gmail.com | Z6: hariomrai.fullstack@gmail.com | AA6: jadhavyogeshdharamsigh.fullstack@gmail.com | AB6: ksantoshi.fullstack@gmail.com | AC6: kaligotaniharika.itesites@gmail.com | AD6: kalpanakodari.fullstack@gmail.com | AE6: kanchaakash.fullstack@gmail.com | AF6: kasturisaimahesh.fullstack@gmail.com | AG6: lovetiwari.fullstack@gmail.com | AH6: mbalaji.itesites@gmail.com | AI6: madhivaishnavi.itesites@gmail.com | AJ6: mandalojunagalaxmi.fullstack@gmail.com | AK6: manikyalaramadevi.fullstack@gmail.com | AL6: maskapavani.itesites@gmail.com | AM6: meghagnimukherjee.fullstack@gmail.com | AN6: nlaxminarasimha.fullstack@gmail.com | AO6: nanapurajlaharika.itesites@gmail.com | AP6: narravenkatasai.itesites@gmail.com | AQ6: navudutejesh.itesites@gmail.com | AR6: palleyshravani.itesites@gmail.com | AS6: papakantiraju.fullstack@gmail.com | AT6: pratapagirineelakantasastry.fullstack@gmail.com | AU6: praveenrajpoot.fullstack@gmail.com | AV6: rvignesh.itesites@gmail.com | AW6: rachamanduguajaykumar.fullstack@gmail.com | AX6: revallinageshwari.fullstack@gmail.com | AY6: rohitreddy.itesites@gmail.com | AZ6: ruchiranjan.fullstack@gmail.com | BA6: shaikfahad.itesites@gmail.com | BB6: shaiksameerahmed.fullstack@gmail.com | BC6: shejulbalajirameshwar.fullstack@gmail.com | BD6: shoaibakhtar.fullstack@gmail.com | BE6: singamkrishnaveni.fullstack@gmail.com | BF6: singudasupallavi.fullstack@gmail.com | BG6: subhashispal.itesites@gmail.com | BH6: sujeetkumar.fullstack@gmail.com | BI6: suruchiranjan.fullstack@gmail.com | BJ6: suvendukhatua.itesites@gmail.com | BK6: syedabdulhakeem.fullstack@gmail.com | BL6: syedabdulhaleem.fullstack@gmail.com | BM6: syedadil.itesites@gmail.com | BN6: velupulasunilkumar.fullstack@gmail.com | BO6: balachary.itesites@gmail.com | BP6: bandarisrujana.fullstack@gmail.com | BQ6: durgaprasad.fullstack@gmail.com | BR6: kpavani.fullstack@gmail.com | BS6: mkomalraj.itesites@gmail.com | BT6: medisangeetha.fullstack@gmail.com | BU6: nparamesh.fullstack@gmail.com | BV6: nagachanduv.itesites@gmail.com | BW6: ssameer.fullstack@gmail.com | BX6: salvadivenkatesh.itesites@gmail.com | BY6: uppunuthalapurushotham.itesites@gmail.com | BZ6: vinaykumar.fullstack@gmail.com | CA6: yarranavyasahithi.fullstack@gmail.com | CB6: maravind.fullstack@gmail.com | CC6: suryakiran.fullstack@gmail.com | CD6: baravind.fullstack@gmail.com
B7: Gender | C7: Female | D7: Female | E7: Male | F7: Male | G7: Male | H7: Male | I7: Male | J7: Male | K7: Female | L7: Female | M7: Male | N7: Male | O7: Female | P7: Male | Q7: Female | R7: Male | S7: Female | T7: Female | U7: Female | V7: Male | W7: Female | X7: Male | Y7: Female | Z7: Male | AA7: Male | AB7: Female | AC7: Female | AD7: Female | AE7: Male | AF7: Male | AG7: Male | AH7: Male | AI7: Female | AJ7: Female | AK7: Female | AL7: Female | AM7: Female | AN7: Male | AO7: Female | AP7: Male | AQ7: Male | AR7: Female | AS7: Male | AT7: Male | AU7: Male | AV7: Male | AW7: Male | AX7: Female | AY7: Male | AZ7: Female | BA7: Male | BB7: Male | BC7: Male | BD7: Male | BE7: Female | BF7: Female | BG7: Male | BH7: Male | BI7: Female | BJ7: Male | BK7: Male | BL7: Male | BM7: Male | BN7: Male | BO7: Male | BP7: Female | BQ7: Male | BR7: Female | BS7: Male | BT7: Female | BU7: Male | BV7: Male | BW7: Male | BX7: Male | BY7: Male | BZ7: Male | CA7: Female | CB7: Male | CC7: Male | CD7: Male

Sheet HResult
F7: Enrollment number | G7: Name of the Student | H7: Specialization
F8: 0223CPIT046 | G8: =HLOOKUP($F$8,HData!$C$2:$CD$7,2,FALSE) -> R. VIGNESH | H8: =HLOOKUP($F$8,HData!$C$2:$CD$7,3,FALSE) -> ITES

Sheet Liminations
B1: Enrollment number | C1: Name of the Student | D1: Specialization | E1: MobileNo | F1: Mail IDs | G1: Gender
B2: 0223CPIT001 | C2: NIKITHA ADULA | D2: ITES | E2: 6399221384 | F2: nikitha.itesites@gmail.com | G2: Female
B3: 0223CPIT002 | C3: ADULA LIKHITHA | D3: Full Stack | E3: 8732960724 | F3: adulalikitha.fullstack@gmail.com | G3: Female
B4: 0223CPIT003 | C4: AKASH RAJPOOT | D4: Full Stack | E4: 3928683138 | F4: akashrajpoot.fullstack@gmail.com | G4: Male
B5: 0223CPIT004 | C5: ALOK KUMAR | D5: Full Stack | E5: 6302977515 | F5: alokkumar.fullstack@gmail.com | G5: Male
B6: 0223CPIT005 | C6: AYUSHMAN SINGH BAGHEL | D6: Full Stack | E6: 3285643454 | F6: ayushmansinghbaghel.fullstack@gmail.com | G6: Male
B7: 0223CPIT006 | C7: B SANDEEP ROY | D7: ITES | E7: 6204804746 | F7: bsandeeproy.itesites@gmail.com | G7: Male | I7: Enrollment number | J7: Name of the Student | K7: Specialization | L7: MobileNo
B8: 0223CPIT007 | C8: B. SRINIVASULU | D8: Full Stack | E8: 8402592334 | F8: bsrinivasulu.fullstack@gmail.com | G8: Male | I8: 0223CPIT006 | J8: =VLOOKUP($I$8,$B$2:$G$81,2,FALSE) -> B SANDEEP ROY | K8: =VLOOKUP($I$8,$B$2:$G$81,3,FALSE) -> ITES | L8: =VLOOKUP($I$8,$B$2:$G$81,4,FALSE) -> 6204804746
B9: 0223CPIT008 | C9: BAIRI PRATHYUSH | D9: Full Stack | E9: 1770577932 | F9: bairiprathyush.fullstack@gmail.com | G9: Male
B10: 0223CPIT009 | C10: BANDAPALLI GANGABHAVANI | D10: ITES | E10: 1087593685 | F10: bandapalligangabhavani.itesites@gmail.com | G10: Female
B11: 0223CPIT010 | C11: BURRI VINITHA | D11: Full Stack | E11: 1693682470 | F11: burrivinitha.fullstack@gmail.com | G11: Female
B12: 0223CPIT011 | C12: CHANDRA SAMPATH KUMAR | D12: Full Stack | E12: 1821308586 | F12: chandrasampathkumar.fullstack@gmail.com | G12: Male
B13: 0223CPIT012 | C13: CHINNAKOTLA SURYA TEJA | D13: Full Stack | E13: 1683546545 | F13: chinnakotlasuryateja.fullstack@gmail.com | G13: Male | I13: Enrollment number | J13: Specialization
B14: 0223CPIT013 | C14: DASARI VIMALA | D14: Full Stack | E14: 5506439807 | F14: dasarivimala.fullstack@gmail.com | G14: Female | I14: 0223CPIT006 | J14: =VLOOKUP($I$8,$B$2:$G$81,3,FALSE) -> ITES
B15: 0223CPIT014 | C15: DEVALLA DEEPAK | D15: ITES | E15: 3565997600 | F15: devalladeepak.itesites@gmail.com | G15: Male
B16: 0223CPIT015 | C16: DEVKATHE KOMAL | D16: Full Stack | E16: 2685014153 | F16: devkathekomal.fullstack@gmail.com | G16: Female
B17: 0223CPIT016 | C17: EERAMMAGARI RAVITEJA | D17: Full Stack | E17: 8144007188 | F17: eerammagariraviteja.fullstack@gmail.com | G17: Male
B18: 0223CPIT017 | C18: ELLENDULA SUPRIYA | D18: ITES | E18: 5451418853 | F18: ellendulasupriya.itesites@gmail.com | G18: Female
B19: 0223CPIT018 | C19: GADIYARAM VARSHA | D19: Full Stack | E19: 2352093828 | F19: gadiyaramvarsha.fullstack@gmail.com | G19: Female
B20: 0223CPIT019 | C20: GAIKWAD SRUSHTI | D20: Full Stack | E20: 4851546652 | F20: gaikwadsrushti.fullstack@gmail.com | G20: Female
B21: 0223CPIT020 | C21: GAJJELA GIRI | D21: ITES | E21: 6604423032 | F21: gajjelagiri.itesites@gmail.com | G21: Male
B22: 0223CPIT021 | C22: GARAPATI GAYATHRI | D22: ITES | E22: 4267924443 | F22: garapatigayathri.itesites@gmail.com | G22: Female
B23: 0223CPIT022 | C23: GOLI SAI LOKESH | D23: Full Stack | E23: 2776428499 | F23: golisailokesh.fullstack@gmail.com | G23: Male
B24: 0223CPIT023 | C24: GURRAM YAMINI | D24: Full Stack | E24: 2344591250 | F24: gurramyamini.fullstack@gmail.com | G24: Female
B25: 0223CPIT024 | C25: HARI OM RAI | D25: Full Stack | E25: 4564000793 | F25: hariomrai.fullstack@gmail.com | G25: Male
B26: 0223CPIT025 | C26: JADHAV YOGESH DHARAMSIGH | D26: Full Stack | E26: 7831800139 | F26: jadhavyogeshdharamsigh.fullstack@gmail.com | G26: Male
... B81: 0223CPIT080 | C81: B Aravind | D81: Full Stack | E81: 2217423855 | F81: baravind.fullstack@gmail.com | G81: Male

Sheet IndexAndMatch
A1: Enrollment number | C1: Name of the Student | D1: Specialization | E1: MobileNo
A2: 0223CPIT001 | C2: NIKITHA ADULA | D2: ITES | E2: 6399221384
A3: 0223CPIT002 | C3: ADULA LIKHITHA | D3: Full Stack | E3: 8732960724
A4: 0223CPIT003 | C4: AKASH RAJPOOT | D4: Full Stack | E4: 3928683138 | H4: Index MultiColumn | I4: Index Single Column
A5: 0223CPIT004 | C5: ALOK KUMAR | D5: Full Stack | E5: 6302977515 | H5: =INDEX($A$2:$E$81,10,2) -> 0 | I5: =INDEX(C2:C1000,10) -> BURRI VINITHA
A6: 0223CPIT005 | C6: AYUSHMAN SINGH BAGHEL | D6: Full Stack | E6: 3285643454 | H6: =INDEX($A$2:$E$81,10,4) -> Full Stack | I6: =INDEX($E$2:$E$81,10) -> 1693682470
A7: 0223CPIT006 | C7: B SANDEEP ROY | D7: ITES | E7: 6204804746
A8: 0223CPIT007 | C8: B. SRINIVASULU | D8: Full Stack | E8: 8402592334
A9: 0223CPIT008 | C9: BAIRI PRATHYUSH | D9: Full Stack | E9: 1770577932
A10: 0223CPIT009 | C10: BANDAPALLI GANGABHAVANI | D10: ITES | E10: 1087593685
A11: 0223CPIT010 | C11: BURRI VINITHA | D11: Full Stack | E11: 1693682470 | H11: Match
A12: 0223CPIT011 | C12: CHANDRA SAMPATH KUMAR | D12: Full Stack | E12: 1821308586 | G12: 0223CPIT020 | H12: =MATCH($G$12,$A$2:$A$82,0) -> 20
A13: 0223CPIT012 | C13: CHINNAKOTLA SURYA TEJA | D13: Full Stack | E13: 1683546545
A14: 0223CPIT013 | C14: DASARI VIMALA | D14: Full Stack | E14: 5506439807
A15: 0223CPIT014 | C15: DEVALLA DEEPAK | D15: ITES | E15: 3565997600
A16: 0223CPIT015 | C16: DEVKATHE KOMAL | D16: Full Stack | E16: 2685014153 | H16: Index And Match
A17: 0223CPIT016 | C17: EERAMMAGARI RAVITEJA | D17: Full Stack | E17: 8144007188 | H17: Enrollment number | I17: Name of the Student | J17: Specialization | K17: MobileNo
A18: 0223CPIT017 | C18: ELLENDULA SUPRIYA | D18: ITES | E18: 5451418853 | H18: 0223CPIT026 | I18: =INDEX($A$2:$E$82,MATCH($H$18,$A$2:$A$82,0),2) -> 0 | J18: =INDEX($A$2:$E$82,MATCH($H$18,$A$2:$A$82,0),3) -> K. SANTOSHI | K18: =INDEX($A$2:$E$82,MATCH($H$18,$A$2:$A$82,0),4) -> Full Stack
A19: 0223CPIT018 | C19: GADIYARAM VARSHA | D19: Full Stack | E19: 2352093828 | I19: =INDEX($A$2:$E$82,MATCH($H$18,$A$2:$A$82,0),MATCH($I$17,$A$1:$E$1,0)) -> K. SANTOSHI
A20: 0223CPIT019 | C20: GAIKWAD SRUSHTI | D20: Full Stack | E20: 4851546652
A21: 0223CPIT020 | C21: GAJJELA GIRI | D21: ITES | E21: 6604423032
A22: 0223CPIT021 | C22: GARAPATI GAYATHRI | D22: ITES | E22: 4267924443 | H22: Index And Match
A23: 0223CPIT022 | C23: GOLI SAI LOKESH | D23: Full Stack | E23: 2776428499 | H23: Enrollment number | I23: Name of the Student | J23: Specialization | K23: MobileNo
A24: 0223CPIT023 | C24: GURRAM YAMINI | D24: Full Stack | E24: 2344591250 | H24: 0223CPIT054 | I24: =INDEX($A$2:$E$82,MATCH($H$24,$A$2:$A$82,0),2) -> 0 | J24: =INDEX($A$2:$E$82,MATCH($H$24,$A$2:$A$82,0),3) -> SHOAIB AKHTAR | K24: =INDEX($A$2:$E$82,MATCH($H$24,$A$2:$A$82,0),4) -> Full Stack
A25: 0223CPIT024 | C25: HARI OM RAI | D25: Full Stack | E25: 4564000793 | H25: 0223CPIT054 | I25: =INDEX($A$2:$E$82,MATCH($H25,$A$2:$A$82,0),MATCH(I$23,$A$1:$E$1,0)) -> SHOAIB AKHTAR | J25: =INDEX($A$2:$E$82,MATCH($H25,$A$2:$A$82,0),MATCH(J$23,$A$1:$E$1,0)) -> Full Stack | K25: =INDEX($A$2:$E$82,MATCH($H25,$A$2:$A$82,0),MATCH(K$23,$A$1:$E$1,0)) -> 7998839021
A26: 0223CPIT025 | C26: JADHAV YOGESH DHARAMSIGH | D26: Full Stack | E26: 7831800139 | H26: 0223CPIT032 | I26: =INDEX($A$2:$E$82,MATCH($H26,$A$2:$A$82,0),MATCH(I$23,$A$1:$E$1,0)) -> M. BALAJI | J26: =INDEX($A$2:$E$82,MATCH($H26,$A$2:$A$82,0),MATCH(J$23,$A$1:$E$1,0)) -> ITES | K26: =INDEX($A$2:$E$82,MATCH($H26,$A$2:$A$82,0),MATCH(K$23,$A$1:$E$1,0)) -> 7375541777
A27: 0223CPIT026 | C27: K. SANTOSHI | D27: Full Stack | E27: 1359937879 | H27: 0223CPIT021 | I27: =INDEX($A$2:$E$82,MATCH($H27,$A$2:$A$82,0),MATCH(I$23,$A$1:$E$1,0)) -> GARAPATI GAYATHRI | J27: =INDEX($A$2:$E$82,MATCH($H27,$A$2:$A$82,0),MATCH(J$23,$A$1:$E$1,0)) -> ITES | K27: =INDEX($A$2:$E$82,MATCH($H27,$A$2:$A$82,0),MATCH(K$23,$A$1:$E$1,0)) -> 4267924443
A28: 0223CPIT027 | C28: KALIGOTA NIHARIKA | D28: ITES | E28: 8357059907
A29: 0223CPIT028 | C29: KALPANA KODARI | D29: Full Stack | E29: 8195300576
A30: 0223CPIT029 | C30: KANCHA AKASH | D30: Full Stack | E30: 3908490120
A31: 0223CPIT030 | C31: KASTURI SAI MAHESH | D31: Full Stack | E31: 6654686097
A32: 0223CPIT031 | C32: LOVE TIWARI | D32: Full Stack | E32: 3176554504
A33: 0223CPIT032 | C33: M. BALAJI | D33: ITES | E33: 7375541777
A34: 0223CPIT033 | C34: MADHI VAISHNAVI | D34: ITES | E34: 2307603936
A35: 0223CPIT034 | C35: MANDALOJU NAGALAXMI | D35: Full Stack | E35: 7539961295
A36: 0223CPIT035 | C36: MANIKYALA RAMADEVI | D36: Full Stack | E36: 8714929594
A37: 0223CPIT036 | C37: MASKA PAVANI | D37: ITES | E37: 6748495954
A38: 0223CPIT037 | C38: MEGHAGNI MUKHERJEE | D38: Full Stack | E38: 5598318903
A39: 0223CPIT038 | C39: N LAXMI NARASIMHA | D39: Full Stack | E39: 5366755536
... A81: 0223CPIT080 | C81: B Aravind | D81: Full Stack | E81: 2217423855
...

Sheet XLookup
B2: Student Code | C2: StudentName | D2: Attendance % | E2: Aptitude Count
B3: AF05203236 | C3: MACHAPATRI SRIJAN | D3: 96 | E3: 5
B6: Student Code | C6: Student Name | D6: Batch Code | E6: Alias | F6: Actual Center | G6: Center Manager | H6: Start Date | I6: End Date | J6: Funder | K6: Attendance% | L6: Course Level Attendance% | M6: TD Lab Marks% | N6: TD Lab Completion% | O6: Lab Count | P6: Lab Assigned | Q6: MCQ Marks% | R6: MCQ Completion% | S6: MCQ Count | T6: MCQ Assigned | U6: Sprint1% | V6: Sprint2% | W6: iChat% | X6: iChat Count | Y6: Aptitude% | Z6: Aptitute Completion% | AA6: Aptitude Count | AB6: Aptitude Assigned
B7: AF05203236 | C7: MACHAPATRI SRIJAN | D7: ANP-D6211 | E7: DPBA | F7: TSACC | G7: Dinesh Korlana | H7: Apr 27, 2026 | I7: null | J7: ACCENTURE | K7: 96 | L7: 21 | M7: 90 | N7: 100 | O7: 2 | P7: 2 | Q7: 94 | R7: 100 | S7: 2 | T7: 2 | U7: 0 | V7: 0 | W7: 0 | X7: 0 | Y7: 98 | Z7: 100 | AA7: 5 | AB7: 5
